Workbook

Sheet SAP
A1: Анализ данных, кг нефтепродуктов | F1: Данные из бухгалтерского учета SAP
A2: Общий вес продукта согласно выписанной накладной (суммы масс по каждому отсеку автоцистерны- колонка Х) | B2: Фактическая масса с данных весов | C2: Разница между фактическим весом и расчетным весом (Плотность*Объем) указаным в отчете софта весов | D2: Обратный расчет расчетной массы из данных талона на погрузку. Данные на основе которых выписываеться накладная и данные которые должны вводиться в софт весов в колонку 'K' рубрика 'Разница' | E2: Колонка C-D, при отсутствия манипуляций результат равен нулю | F2: Truck Number | G2: Loading Date | H2: Gas Station Number (destination place) | I2: Product density | J2: SAP Product Code | K2: Fuel Type | L2: SAP Company Code (MD18 Rompetrol Moldova) | M2: Loading place | N2: Loading Quantity - Litres | O2: Loading Quantity - Litres 15/20 Degree | P2: Loading Quantity - Kg (Invoced mass) | Q2: Fuel Temperature C | R2: Transport Company | S2: Driver Name | T2: Year
A4: =P4+P5+P6 -> 24343.947 | B4: ='Весы 01.11.2023'!I58 -> 24300 | C4: ='Весы 01.11.2023'!K59 -> -41 | D4: =B4-C4 -> 24341 | E4: =A4-D4 -> 2.947 | F4: SDZ578 / V193LG | G4: 45231 | H4: M076 | I4: 745 | J4: 31EPS10B00 | K4: EURO PLUS GASOLINE | L4: MD18 | M4: Depozit Chisinau | N4: 15410 | O4: 15391.323 | P4: 11480.446 | Q4: 16,00 | R4: Andezit SRL | S4: Popa S. | T4: 2023
F5: SDZ578 / V193LG | G5: 45231 | H5: M076 | I5: 834,50 | J5: 33EFX10B00 | K5: 51 EFIX DIESEL | L5: MD18 | M5: Depozit Chisinau | N5: 7695 | O5: 7688.436 | P5: 6421.477 | Q5: 16,00 | R5: Andezit SRL | S5: Popa S. | T5: 2023
F6: SDZ578 / V193LG | G6: 45231 | H6: M076 | I6: 835,00 | J6: 33ME510000 | K6: EURO 5 DIESEL | L6: MD18 | M6: Depozit Chisinau | N6: 7715 | O6: 7708.427 | P6: 6442.024 | Q6: 16,00 | R6: Andezit SRL | S6: Popa S. | T6: 2023
A7: =P7+P8 -> 26728.347 | B7: ='Весы 01.11.2023'!I57 -> 26710 | C7: ='Весы 01.11.2023'!K57 -> -18 | D7: =B7-C7 -> 26728 | E7: =A7-D7 -> 0.347 | F7: RTL069 / I870WW | G7: 45231 | H7: M073 | I7: 835,00 | J7: 33ME510000 | K7: EURO 5 DIESEL | L7: MD18 | M7: Depozit Chisinau | N7: 20010 | O7: 19992.951 | P7: 16708.348 | Q7: 16,00 | R7: Vero Nadina SRL | S7: Cobzac A. | T7: 2023
F8: RTL069 / I870WW | G8: 45231 | H8: M043 | I8: 835,00 | J8: 33ME510000 | K8: EURO 5 DIESEL | L8: MD18 | M8: Depozit Chisinau | N8: 12000 | O8: 11989.776 | P8: 10019.999 | Q8: 16,00 | R8: Vero Nadina SRL | S8: Cobzac A. | T8: 2023
A9: =P9+P10+P11 -> 26503 | B9: ='Весы 01.11.2023'!I50 -> 26460 | C9: ='Весы 01.11.2023'!K50 -> -43 | D9: =B9-C9 -> 26503 | E9: =A9-D9 -> 0 | F9: SPK940 / NSAB055 | G9: 45231 | H9: M085 | I9: 744,00 | J9: 31EPS10B00 | K9: EURO PLUS GASOLINE | L9: MD18 | M9: Depozit Chisinau | N9: 11000 | O9: 11000 | P9: 8184 | Q9: 15,00 | R9: Vero Nadina SRL | S9: Frunze M. | T9: 2023
F10: SPK940 / NSAB055 | G10: 45231 | H10: M085 | I10: 830,50 | J10: 33EFX10B00 | K10: 51 EFIX DIESEL | L10: MD18 | M10: Depozit Chisinau | N10: 6000 | O10: 6000 | P10: 4983 | Q10: 15,00 | R10: Vero Nadina SRL | S10: Frunze M. | T10: 2023
F11: SPK940 / NSAB055 | G11: 45231 | H11: M085 | I11: 833,50 | J11: 33ME510000 | K11: EURO 5 DIESEL | L11: MD18 | M11: Depozit Chisinau | N11: 16000 | O11: 16000 | P11: 13336 | Q11: 15,00 | R11: Vero Nadina SRL | S11: Frunze M. | T11: 2023
A12: =P12+P13 -> 24835.45 | B12: ='Весы 01.11.2023'!I49 -> 24780 | C12: ='Весы 01.11.2023'!K49 -> -55 | D12: =B12-C12 -> 24835 | E12: =A12-D12 -> 0.45 | F12: FGT903 / A331AB | G12: 45231 | H12: M088 | I12: 744,50 | J12: 31EPS10B00 | K12: EURO PLUS GASOLINE | L12: MD18 | M12: Depozit Chisinau | N12: 10100 | O12: 10100 | P12: 7519.45 | Q12: 15,00 | R12: Vero Nadina SRL | S12: Capatina G. | T12: 2023
F13: FGT903 / A331AB | G13: 45231 | H13: M088 | I13: 832,50 | J13: 33ME510000 | K13: EURO 5 DIESEL | L13: MD18 | M13: Depozit Chisinau | N13: 20800 | O13: 20782.174 | P13: 17316 | Q13: 16,00 | R13: Vero Nadina SRL | S13: Capatina G. | T13: 2023
A14: =P14+P15 -> 25595.758 | B14: ='Весы 01.11.2023'!I54 -> 25570 | C14: ='Весы 01.11.2023'!K54 -> -26 | D14: =B14-C14 -> 25596 | E14: =A14-D14 -> -0.242 | F14: LUQ250 / NSAB041 | G14: 45231 | H14: M034 | I14: 744,50 | J14: 31EPS10B00 | K14: EURO PLUS GASOLINE | L14: MD18 | M14: Depozit Chisinau | N14: 12895 | O14: 12895 | P14: 9600.328 | Q14: 15,00 | R14: Vero Nadina SRL | S14: Postolache V. | T14: 2023
F15: LUQ250 / NSAB041 | G15: 45231 | H15: M034 | I15: 830,50 | J15: 33ME510000 | K15: EURO 5 DIESEL | L15: MD18 | M15: Depozit Chisinau | N15: 19260 | O15: 19260 | P15: 15995.43 | Q15: 15,00 | R15: Vero Nadina SRL | S15: Postolache V. | T15: 2023
A16: =P16+P17 -> 24381.381 | B16: ='Весы 01.11.2023'!I59 -> 24340 | C16: ='Весы 01.11.2023'!K59 -> -41 | D16: =B16-C16 -> 24381 | E16: =A16-D16 -> 0.381 | F16: RTL067 / NSAA982 | G16: 45231 | H16: M006 | I16: 745,00 | J16: 31EPS10B00 | K16: EURO PLUS GASOLINE | L16: MD18 | M16: Depozit Chisinau | N16: 18585 | O16: 18562.475 | P16: 13845.82 | Q16: 16,00 | R16: Vero Nadina SRL | S16: Batog S. | T16: 2023
F17: RTL067 / NSAA982 | G17: 45231 | H17: M006 | I17: 834,50 | J17: 33EFX10B00 | K17: 51 EFIX DIESEL | L17: MD18 | M17: Depozit Chisinau | N17: 12625 | O17: 12614.231 | P17: 10535.561 | Q17: 16,00 | R17: Vero Nadina SRL | S17: Batog S. | T17: 2023
A18: =P18+P19+P20+P21 -> 26030.264 | B18: ='Весы 01.11.2023'!I66 -> 25990 | C18: ='Весы 01.11.2023'!K66 -> -40 | D18: =B18-C18 -> 26030 | E18: =A18-D18 -> 0.264 | F18: ZGO801 / I175WW | G18: 45231 | H18: M031 | I18: 746,50 | J18: 31EFX10B00 | K18: EFIX 95 GASOLINE | L18: MD18 | M18: Depozit Chisinau | N18: 4700 | O18: 4700 | P18: 3508.55 | Q18: 15,00 | R18: Vero Nadina SRL | S18: Drapac S. | T18: 2023
F19: ZGO801 / I175WW | G19: 45231 | H19: M031 | I19: 745,00 | J19: 31EPS10B00 | K19: EURO PLUS GASOLINE | L19: MD18 | M19: Depozit Chisinau | N19: 9850 | O19: 9838.062 | P19: 7338.247 | Q19: 16,00 | R19: Vero Nadina SRL | S19: Drapac S. | T19: 2023
F20: ZGO801 / I175WW | G20: 45231 | H20: M031 | I20: 835,00 | J20: 33EFX10B00 | K20: 51 EFIX DIESEL | L20: MD18 | M20: Depozit Chisinau | N20: 6020 | O20: 6014.871 | P20: 5026.699 | Q20: 16,00 | R20: Vero Nadina SRL | S20: Drapac S. | T20: 2023
F21: ZGO801 / I175WW | G21: 45231 | H21: M031 | I21: 831,50 | J21: 33ME510000 | K21: EURO 5 DIESEL | L21: MD18 | M21: Depozit Chisinau | N21: 12215 | O21: 12194.039 | P21: 10156.768 | Q21: 17,00 | R21: Vero Nadina SRL | S21: Drapac S. | T21: 2023
A22: =P22+P23+P24 -> 26056.662 | B22: ='Весы 01.11.2023'!I56 -> 26030 | C22: ='Весы 01.11.2023'!K56 -> -27 | D22: =B22-C22 -> 26057 | E22: =A22-D22 -> -0.338 | F22: AAB014 / A014AB | G22: 45231 | H22: M062 | I22: 744,50 | J22: 31EPS10B00 | K22: EURO PLUS GASOLINE | L22: MD18 | M22: Depozit Chisinau | N22: 6980 | O22: 6971.533 | P22: 5196.609 | Q22: 16,00 | R22: Andezit SRL | S22: Cioban V. | T22: 2023
F23: AAB014 / A014AB | G23: 45231 | H23: M062 | I23: 835,50 | J23: 33EFX10B00 | K23: 51 EFIX DIESEL | L23: MD18 | M23: Depozit Chisinau | N23: 6705 | O23: 6699.294 | P23: 5602.027 | Q23: 16,00 | R23: Andezit SRL | S23: Cioban V. | T23: 2023
F24: AAB014 / A014AB | G24: 45231 | H24: M062 | I24: 831,50 | J24: 33ME510000 | K24: EURO 5 DIESEL | L24: MD18 | M24: Depozit Chisinau | N24: 18350 | O24: 18334.237 | P24: 15258.026 | Q24: 16,00 | R24: Andezit SRL | S24: Cioban V. | T24: 2023
A25: =P25+P26+P27 -> 25016.652 | B25: ='Весы 01.11.2023'!I52 -> 24980 | C25: ='Весы 01.11.2023'!K52 -> -37 | D25: =B25-C25 -> 25017 | E25: =A25-D25 -> -0.348 | F25: CRV580 / X199XC | G25: 45231 | H25: M058 | I25: 831,00 | J25: 33ME510000 | K25: EURO 5 DIESEL | L25: MD18 | M25: Depozit Chisinau | N25: 16700 | O25: 16685.638 | P25: 13877.701 | Q25: 16,00 | R25: Andezit SRL | S25: Gusan I. | T25: 2023
F26: CRV580 / X199XC | G26: 45231 | H26: M058 | I26: 744,00 | J26: 31EPS10B00 | K26: EURO PLUS GASOLINE | L26: MD18 | M26: Depozit Chisinau | N26: 9700 | O26: 9688.224 | P26: 7216.801 | Q26: 16,00 | R26: Andezit SRL | S26: Gusan I. | T26: 2023
F27: CRV580 / X199XC | G27: 45231 | H27: M058 | I27: 834,50 | J27: 33EFX10B00 | K27: 51 EFIX DIESEL | L27: MD18 | M27: Depozit Chisinau | N27: 4700 | O27: 4695.991 | P27: 3922.15 | Q27: 16,00 | R27: Andezit SRL | S27: Gusan I. | T27: 2023
A28: =P28+P29+P30 -> 25208.343 | B28: ='Весы 01.11.2023'!I53 -> 25160 | C28: ='Весы 01.11.2023'!K53 -> -48 | D28: =B28-C28 -> 25208 | E28: =A28-D28 -> 0.343 | F28: KBC073 / A012AB | G28: 45231 | H28: M100 | I28: 749,00 | J28: 31EFX10B00 | K28: EFIX 95 GASOLINE | L28: MD18 | M28: Depozit Chisinau | N28: 4380 | O28: 4395.886 | P28: 3280.621 | Q28: 12,00 | R28: Andezit SRL | S28: Puiu V. | T28: 2023
F29: KBC073 / A012AB | G29: 45231 | H29: M100 | I29: 744,00 | J29: 31EPS10B00 | K29: EURO PLUS GASOLINE | L29: MD18 | M29: Depozit Chisinau | N29: 13925 | O29: 13908.095 | P29: 10360.201 | Q29: 16,00 | R29: Andezit SRL | S29: Puiu V. | T29: 2023
F30: KBC073 / A012AB | G30: 45231 | H30: M100 | I30: 831,00 | J30: 33ME510000 | K30: EURO 5 DIESEL | L30: MD18 | M30: Depozit Chisinau | N30: 13920 | O30: 13908.029 | P30: 11567.521 | Q30: 16,00 | R30: Andezit SRL | S30: Puiu V. | T30: 2023
A31: =P31+P32+P33 -> 25001.678 | B31: ='Весы 01.11.2023'!I60 -> 24970 | C31: ='Весы 01.11.2023'!K60 -> -32 | D31: =B31-C31 -> 25002 | E31: =A31-D31 -> -0.322 | F31: CRV530 / V189LG | G31: 45231 | H31: M029 | I31: 744,50 | J31: 31EPS10B00 | K31: EURO PLUS GASOLINE | L31: MD18 | M31: Depozit Chisinau | N31: 7670 | O31: 7660.696 | P31: 5710.314 | Q31: 16,00 | R31: Andezit SRL | S31: Brodescu A. | T31: 2023
F32: CRV530 / V189LG | G32: 45231 | H32: M029 | I32: 835,00 | J32: 33EFX10B00 | K32: 51 EFIX DIESEL | L32: MD18 | M32: Depozit Chisinau | N32: 7695 | O32: 7688.444 | P32: 6425.324 | Q32: 16,00 | R32: Andezit SRL | S32: Brodescu A. | T32: 2023
F33: CRV530 / V189LG | G33: 45231 | H33: M029 | I33: 836,00 | J33: 33ME510000 | K33: EURO 5 DIESEL | L33: MD18 | M33: Depozit Chisinau | N33: 15390 | O33: 15390 | P33: 12866.04 | Q33: 15,00 | R33: Andezit SRL | S33: Brodescu A. | T33: 2023
A34: =SUM(P34:P36) -> 25570.621 | B34: ='Весы 01.11.2023'!I62 -> 25540 | C34: ='Весы 01.11.2023'!K62 -> -31 | D34: =B34-C34 -> 25571 | E34: =A34-D34 -> -0.379 | F34: AAK103 / V203LG | G34: 45231 | H34: M081 | I34: 835,00 | J34: 33EFX10B00 | K34: 51 EFIX DIESEL | L34: MD18 | M34: Depozit Chisinau | N34: 7700 | O34: 7693.44 | P34: 6429.499 | Q34: 16,00 | R34: Andezit SRL | S34: Casap A. | T34: 2023
F35: AAK103 / V203LG | G35: 45231 | H35: M081 | I35: 831,50 | J35: 33ME510000 | K35: EURO 5 DIESEL | L35: MD18 | M35: Depozit Chisinau | N35: 15355 | O35: 15328.651 | P35: 12767.677 | Q35: 17,00 | R35: Andezit SRL | S35: Casap A. | T35: 2023
F36: AAK103 / V203LG | G36: 45231 | H36: M079 | I36: 831,50 | J36: 33ME510000 | K36: EURO 5 DIESEL | L36: MD18 | M36: Depozit Chisinau | N36: 7665 | O36: 7651.847 | P36: 6373.445 | Q36: 17,00 | R36: Andezit SRL | S36: Casap A. | T36: 2023
A37: =P37+P38 -> 19417.965 | B37: ='Весы 01.11.2023'!I51 -> 19400 | C37: ='Весы 01.11.2023'!K51 -> -18 | D37: =B37-C37 -> 19418 | E37: =A37-D37 -> -0.035 | F37: NSAR887 / | G37: 45231 | H37: M099 | I37: 833,00 | J37: 33ME510000 | K37: EURO 5 DIESEL | L37: MD18 | M37: Depozit Chisinau | N37: 16965 | O37: 16965 | P37: 14131.845 | Q37: 15,00 | R37: Vero Nadina SRL | S37: Secrieru N. | T37: 2023
F38: NSAR887 / | G38: 45231 | H38: M099 | I38: 744,00 | J38: 31EPS10B00 | K38: EURO PLUS GASOLINE | L38: MD18 | M38: Depozit Chisinau | N38: 7105 | O38: 7105 | P38: 5286.12 | Q38: 15,00 | R38: Vero Nadina SRL | S38: Secrieru N. | T38: 2023
A39: =P39+P40+P41+P42 -> 26575.253 | B39: ='Весы 01.11.2023'!I55 -> 26530 | C39: ='Весы 01.11.2023'!K55 -> -45 | D39: =B39-C39 -> 26575 | E39: =A39-D39 -> 0.253 | F39: NSAL703 / I854WW | G39: 45231 | H39: M089 | I39: 746,50 | J39: 31EFX10B00 | K39: EFIX 95 GASOLINE | L39: MD18 | M39: Depozit Chisinau | N39: 5000 | O39: 5006.06 | P39: 3732.502 | Q39: 14,00 | R39: Vero Nadina SRL | S39: Zghibart V. | T39: 2023
F40: NSAL703 / I854WW | G40: 45231 | H40: M089 | I40: 835,50 | J40: 33EFX10B00 | K40: 51 EFIX DIESEL | L40: MD18 | M40: Depozit Chisinau | N40: 6500 | O40: 6494.468 | P40: 5430.749 | Q40: 16,00 | R40: Vero Nadina SRL | S40: Zghibart V. | T40: 2023
F41: NSAL703 / I854WW | G41: 45231 | H41: M089 | I41: 831,00 | J41: 33ME510000 | K41: EURO 5 DIESEL | L41: MD18 | M41: Depozit Chisinau | N41: 12000 | O41: 11989.68 | P41: 9972.001 | Q41: 16,00 | R41: Vero Nadina SRL | S41: Zghibart V. | T41: 2023
...

Sheet Весы 08.11.2023
A1: Шаблон отчета с группировкой по складам
A3: за период по контрагенту по перевозчику по материалу по складу по транспорту по направлению | C3: 08.11.2023-08.11.2023 <ВСЕ> <ВСЕ> <ВСЕ> <ВСЕ> <ВСЕ> <Любое>
A5: Дата создания | D5: Номер | E5: Накладная | F5: Брутто | G5: Тара | H5: Получено | I5: Отпущено | K5: Разница кг | L5: Контрагент | M5: Склад | O5: Перевозчик
A6: 11.08.23 | D6: T514NJ | E6: PR405097 | F6: 39440 | G6: 13360 | H6: 26080 | K6: -87 | L6: Rafinaria Navodari | M6: Benzina ADT | O6: Andezit
A8: Итого по Benzina ADT | H8: 26080 | I8: 0 | K8: На сумму | N8: В т.ч. НДС
F9: По документам | H9: 26167 | I9: 0 | K9: 0,00 | N9: 0,00
A11: Дата создания | D11: Номер | E11: Накладная | F11: Брутто | G11: Тара | H11: Получено | I11: Отпущено | K11: Разница кг | L11: Контрагент | M11: Склад | O11: Перевозчик
A12: 11.08.23 | D12: Z778PT | E12: PR405101 | F12: 39580 | G12: 13410 | H12: 26170 | K12: -88 | L12: Rafinaria Navodari | M12: Benzina Euro | O12: Andezit
A13: 11.08.23 | D13: I856WW | E13: MD0844667 | F13: 39690 | G13: 13100 | H13: 26590 | K13: -59 | L13: Rafinaria Navodari | M13: Benzina Euro | O13: Vero-Nadina
A14: 11.08.23 | D14: I288WW | E14: MD0844666 | F14: 39240 | G14: 12650 | H14: 26590 | K14: -90 | L14: Rafinaria Navodari | M14: Benzina Euro | O14: Vero-Nadina
A15: 11.08.23 | D15: H917TZ | E15: PR405105 | F15: 39850 | G15: 13000 | H15: 26850 | K15: -64 | L15: Rafinaria Navodari | M15: Benzina Euro | O15: Andezit
A16: 11.08.23 | D16: X175CC | E16: PR404701 | F16: 38780 | G16: 13770 | H16: 25010 | K16: -126 | L16: Rafinaria Navodari | M16: Benzina Euro | O16: Andezit
A17: 11.08.23 | D17: S635JG | E17: PR405134 | F17: 39170 | G17: 12570 | H17: 26600 | K17: -76 | L17: Rafinaria Navodari | M17: Benzina Euro | O17: Andezit
A18: 11.08.23 | D18: M673VI | E18: PR405120 | F18: 39180 | G18: 12710 | H18: 26470 | K18: -102 | L18: Rafinaria Navodari | M18: Benzina Euro | O18: Andezit
A20: Итого по Benzina Euro | H20: 184280 | I20: 0 | K20: На сумму | N20: В т.ч. НДС
F21: По документам | H21: 184885 | I21: 0 | K21: 0,00 | N21: 0,00
A23: Дата создания | D23: Номер | E23: Накладная | F23: Брутто | G23: Тара | H23: Получено | I23: Отпущено | K23: Разница кг | L23: Контрагент | M23: Склад | O23: Перевозчик
A24: 11.08.23 | D24: C922RA | E24: PR405099 | F24: 39350 | G24: 13870 | H24: 25480 | K24: -82 | L24: Rafinaria Navodari | M24: Motorina ADT | O24: Andezit
A25: 11.08.23 | D25: I695WW | E25: MD0809486 | F25: 39110 | G25: 12160 | H25: 26950 | K25: -68 | L25: Rafinaria Navodari | M25: Motorina ADT | O25: Vero-Nadina
A26: 11.08.23 | D26: Y367CQ | E26: PR405107 | F26: 39470 | G26: 12850 | H26: 26620 | K26: -84 | L26: Rafinaria Navodari | M26: Motorina ADT | O26: Andezit
A28: Итого по Motorina ADT | H28: 79050 | I28: 0 | K28: На сумму | N28: В т.ч. НДС
F29: По документам | H29: 79284 | I29: 0 | K29: 0,00 | N29: 0,00
A31: Дата создания | D31: Номер | E31: Накладная | F31: Брутто | G31: Тара | H31: Получено | I31: Отпущено | K31: Разница кг | L31: Контрагент | M31: Склад | O31: Перевозчик
A32: 11.08.23 | D32: I699WW | E32: AAO1574298 | F32: 40010 | G32: 12660 | H32: 27350 | K32: -140 | L32: Giurgiulesti | M32: Motorina Euro | O32: Vero-Nadina
A33: 11.08.23 | D33: C919RA | E33: AAO1574299 | F33: 39800 | G33: 13890 | H33: 25910 | K33: -68 | L33: Giurgiulesti | M33: Motorina Euro | O33: Andezit
A34: 11.08.23 | D34: T521NJ | E34: PR404953 | F34: 39600 | G34: 13510 | H34: 26090 | K34: -127 | L34: Rafinaria Navodari | M34: Motorina Euro | O34: Andezit
A35: 11.08.23 | D35: C818RB | E35: AAO1574300 | F35: 38580 | G35: 12090 | H35: 26490 | K35: -79 | L35: Giurgiulesti | M35: Motorina Euro | O35: Andezit
A36: 11.08.23 | D36: I289WW | E36: AAO1574301 | F36: 39270 | G36: 13470 | H36: 25800 | K36: -56 | L36: Giurgiulesti | M36: Motorina Euro | O36: Vero-Nadina
A37: 11.08.23 | D37: C920RA | E37: AAO1574302 | F37: 39410 | G37: 13690 | H37: 25720 | K37: -70 | L37: Giurgiulesti | M37: Motorina Euro | O37: Andezit
A38: 11.08.23 | D38: S640JG | E38: AAO1574303 | F38: 39890 | G38: 13490 | H38: 26400 | K38: -92 | L38: Giurgiulesti | M38: Motorina Euro | O38: Andezit
A39: 11.08.23 | D39: I320WW | E39: AAO1574304 | F39: 39950 | G39: 13480 | H39: 26470 | K39: -105 | L39: Giurgiulesti | M39: Motorina Euro | O39: Vero-Nadina
A40: 11.08.23 | D40: I175WW | E40: AAO1574308 | F40: 40650 | G40: 13470 | H40: 27180 | K40: -40 | L40: Giurgiulesti | M40: Motorina Euro | O40: Vero-Nadina
A41: 11.08.23 | D41: S667JG | E41: AAO1574306 | F41: 39840 | G41: 13430 | H41: 26410 | K41: -17 | L41: Giurgiulesti | M41: Motorina Euro | O41: Vero-Nadina
A42: 11.08.23 | D42: I961WW | E42: PR405104 | F42: 39050 | G42: 13390 | H42: 25660 | K42: -85 | L42: Rafinaria Navodari | M42: Motorina Euro | O42: Andezit
A43: 11.08.23 | D43: V778LG | E43: PR405119 | F43: 39640 | G43: 13370 | H43: 26270 | K43: -86 | L43: Rafinaria Navodari | M43: Motorina Euro | O43: Andezit
... A51: 11.08.23 | D51: C813AW | E51: AAO1574305 | F51: 39220 | G51: 12930 | H51: 26290 | K51: -99 | L51: Giurgiulesti | M51: Motorina Euro | O51: Andezit
A53: Итого по Motorina Euro | H53: 524400 | I53: 0 | K53: На сумму | N53: В т.ч. НДС
F54: По документам | H54: 526092 | I54: 0 | K54: 0,00 | N54: 0,00
A56: Дата создания | D56: Номер | E56: Накладная | F56: Брутто | G56: Тара | H56: Получено | I56: Отпущено | K56: Разница кг | L56: Контрагент | M56: Склад | O56: Перевозчик
A57: 11.08.23 | D57: NSAB055 | E57: AAE7651704 | F57: 40060 | G57: 13540 | I57: 26520 | K57: -37 | L57: Depozit Chisinau | M57: Diferite | O57: Vero-Nadina
...

Sheet Весы 07.11.2023
A1: Шаблон отчета с группировкой по складам
A3: за период по контрагенту по перевозчику по материалу по складу по транспорту по направлению | C3: 07.11.2023-07.11.2023 <ВСЕ> <ВСЕ> <ВСЕ> <ВСЕ> <ВСЕ> <Любое>
A5: Дата создания | D5: Номер | E5: Накладная | F5: Брутто | G5: Тара | H5: Получено | I5: Отпущено | K5: Разница кг | L5: Контрагент | M5: Склад | O5: Перевозчик
A6: 11.07.23 | D6: S641JG | E6: PR405092 | F6: 39810 | G6: 13020 | H6: 26790 | K6: -80 | L6: Rafinaria Navodari | M6: Benzina Euro | O6: Andezit
A7: 11.07.23 | D7: M607VI | E7: MD0810035 | F7: 39350 | G7: 13660 | H7: 25690 | K7: -57 | L7: Rafinaria Navodari | M7: Benzina Euro | O7: Vero-Nadina
A8: 11.07.23 | D8: L690MM | E8: MD0809236 | F8: 39100 | G8: 13330 | H8: 25770 | K8: -110 | L8: Rafinaria Navodari | M8: Benzina Euro | O8: Vero-Nadina
A9: 11.07.23 | D9: O911FC | E9: MD0844644 | F9: 39520 | G9: 12890 | H9: 26630 | K9: -69 | L9: Rafinaria Navodari | M9: Benzina Euro | O9: Vero-Nadina
A10: 11.07.23 | D10: I855WW | E10: MD0844693 | F10: 39380 | G10: 13190 | H10: 26190 | K10: -61 | L10: Rafinaria Navodari | M10: Benzina Euro | O10: Vero-Nadina
A12: Итого по Benzina Euro | H12: 131070 | I12: 0 | K12: На сумму | N12: В т.ч. НДС
F13: По документам | H13: 131447 | I13: 0 | K13: 0,00 | N13: 0,00
A15: Дата создания | D15: Номер | E15: Накладная | F15: Брутто | G15: Тара | H15: Получено | I15: Отпущено | K15: Разница кг | L15: Контрагент | M15: Склад | O15: Перевозчик
A16: 11.07.23 | D16: BV94LKT | F16: 39360 | G16: 11540 | H16: 27820 | K16: -88 | L16: Rafinaria Navodari | M16: Motorina ADT | O16: LCT
A17: 11.07.23 | D17: BV92LKT | F17: 39860 | G17: 11830 | H17: 28030 | K17: -53 | L17: Rafinaria Navodari | M17: Motorina ADT | O17: LCT
A19: Итого по Motorina ADT | H19: 55850 | I19: 0 | K19: На сумму | N19: В т.ч. НДС
F20: По документам | H20: 55991 | I20: 0 | K20: 0,00 | N20: 0,00
A22: Дата создания | D22: Номер | E22: Накладная | F22: Брутто | G22: Тара | H22: Получено | I22: Отпущено | K22: Разница кг | L22: Контрагент | M22: Склад | O22: Перевозчик
A23: 11.07.23 | D23: BV87LKT | F23: 39930 | G23: 12480 | H23: 27450 | K23: -92 | L23: Rafinaria Navodari | M23: Motorina Euro | O23: LCT
A24: 11.07.23 | D24: BV54LKT | F24: 39740 | G24: 11850 | H24: 27890 | K24: -77 | L24: Rafinaria Navodari | M24: Motorina Euro | O24: LCT
A25: 11.07.23 | D25: C919RA | E25: AAO1574291 | F25: 39850 | G25: 13940 | H25: 25910 | K25: -53 | L25: Giurgiulesti | M25: Motorina Euro | O25: Andezit
A26: 11.07.23 | D26: C823AW | E26: PR405090 | F26: 39620 | G26: 13110 | H26: 26510 | K26: -72 | L26: Rafinaria Navodari | M26: Motorina Euro | O26: Andezit
A27: 11.07.23 | D27: I320WW | E27: AAO1574289 | F27: 40340 | G27: 13540 | H27: 26800 | K27: -50 | L27: Giurgiulesti | M27: Motorina Euro | O27: Vero-Nadina
A28: 11.07.23 | D28: C818RB | E28: AAO15574290 | F28: 38790 | G28: 12240 | H28: 26550 | K28: -47 | L28: Giurgiulesti | M28: Motorina Euro | O28: Andezit
A29: 11.07.23 | D29: NSAA982 | E29: AAO1574293 | F29: 41060 | G29: 15120 | H29: 25940 | K29: -44 | L29: Giurgiulesti | M29: Motorina Euro | O29: Vero-Nadina
A30: 11.07.23 | D30: I289WW | E30: AAO1574292 | F30: 39150 | G30: 13540 | H30: 25610 | K30: -60 | L30: Giurgiulesti | M30: Motorina Euro | O30: Vero-Nadina
A31: 11.07.23 | D31: S640JG | E31: AAO1574296 | F31: 39950 | G31: 13550 | H31: 26400 | K31: -123 | L31: Giurgiulesti | M31: Motorina Euro | O31: Andezit
A32: 11.07.23 | D32: S667JG | E32: AAO1574295 | F32: 39930 | G32: 13590 | H32: 26340 | K32: -78 | L32: Giurgiulesti | M32: Motorina Euro | O32: Andezit
A33: 11.07.23 | D33: NSAA703 | E33: AAO1574297 | F33: 40220 | G33: 13690 | H33: 26530 | K33: -69 | L33: Giurgiulesti | M33: Motorina Euro | O33: Vero-Nadina
A35: Итого по Motorina Euro | H35: 291930 | I35: 0 | K35: На сумму | N35: В т.ч. НДС
F36: По документам | H36: 292695 | I36: 0 | K36: 0,00 | N36: 0,00
A38: Дата создания | D38: Номер | E38: Накладная | F38: Брутто | G38: Тара | H38: Получено | I38: Отпущено | K38: Разница кг | L38: Контрагент | M38: Склад | O38: Перевозчик
A39: 11.07.23 | D39: BV95LKT | F39: 39590 | G39: 11800 | H39: 27790 | K39: -94 | L39: Rafinaria Navodari | M39: Motorina S55 | O39: LCT
A41: Итого по Motorina S55 | H41: 27790 | I41: 0 | K41: На сумму | N41: В т.ч. НДС
F42: По документам | H42: 27884 | I42: 0 | K42: 0,00 | N42: 0,00
A44: Дата создания | D44: Номер | E44: Накладная | F44: Брутто | G44: Тара | H44: Получено | I44: Отпущено | K44: Разница кг | L44: Контрагент | M44: Склад | O44: Перевозчик
A45: 11.07.23 | D45: NSAB041 | E45: AAE7651710 | F45: 39870 | G45: 13590 | I45: 26280 | K45: -35 | L45: Depozit Chisinau | M45: Diferite | O45: Vero-Nadina
A46: 11.07.23 | D46: NSAR887 | E46: AAE7651711 | F46: 32650 | G46: 13210 | I46: 19440 | K46: -10 | L46: Depozit Chisinau | M46: Diferite | O46: Vero-Nadina
A47: 11.07.23 | D47: NSAB055 | E47: AAE7651712 | F47: 40220 | G47: 13570 | I47: 26650 | K47: -52 | L47: Depozit Chisinau | M47: Diferite | O47: Vero-Nadina
A48: 11.07.23 | D48: V193LG | E48: AAE7651713 | F48: 38020 | G48: 13670 | I48: 24350 | K48: -48 | L48: Depozit Chisinau | M48: Diferite | O48: Andezit
A49: 11.07.23 | D49: I870WW | E49: AAE7651714 | F49: 38630 | G49: 12760 | I49: 25870 | K49: -28 | L49: Depozit Chisinau | M49: Diferite | O49: Vero-Nadina
A50: 11.07.23 | D50: A331AB | E50: AAE7651715 | F50: 38060 | G50: 13180 | I50: 24880 | K50: -41 | L50: Depozit Chisinau | M50: Diferite | O50: Vero-Nadina
...

Sheet Весы 06.11.2023
A1: Шаблон отчета с группировкой по складам
A3: за период по контрагенту по перевозчику по материалу по складу по транспорту по направлению | C3: 06.11.2023-06.11.2023 <ВСЕ> <ВСЕ> <ВСЕ> <ВСЕ> <ВСЕ> <Любое>
A5: Дата создания | D5: Номер | E5: Накладная | F5: Брутто | G5: Тара | H5: Получено | I5: Отпущено | K5: Разница кг | L5: Контрагент | M5: Склад | O5: Перевозчик
A6: 11.06.23 | D6: M673VI | E6: PR405078 | F6: 39250 | G6: 12740 | H6: 26510 | K6: -64 | L6: Rafinaria Navodari | M6: Benzina ADT | O6: Andezit
A7: 11.06.23 | D7: H120TZ | E7: PR405093 | F7: 39710 | G7: 13000 | H7: 26710 | K7: -87 | L7: Rafinaria Navodari | M7: Benzina ADT | O7: Andezit
A8: 11.06.23 | D8: Y698CQ | E8: MD0844782 | F8: 40180 | G8: 14070 | H8: 26110 | K8: -88 | L8: Rafinaria Navodari | M8: Benzina ADT | O8: Vero-Nadina
A9: 11.06.23 | D9: Y202CQ | E9: PR405072 | F9: 39670 | G9: 12630 | H9: 27040 | K9: -104 | L9: Rafinaria Navodari | M9: Benzina ADT | O9: Andezit
A11: Итого по Benzina ADT | H11: 106370 | I11: 0 | K11: На сумму | N11: В т.ч. НДС
F12: По документам | H12: 106713 | I12: 0 | K12: 0,00 | N12: 0,00
A14: Дата создания | D14: Номер | E14: Накладная | F14: Брутто | G14: Тара | H14: Получено | I14: Отпущено | K14: Разница кг | L14: Контрагент | M14: Склад | O14: Перевозчик
A15: 11.06.23 | D15: C825RB | E15: PR405016 | F15: 39970 | G15: 12800 | H15: 27170 | K15: -108 | L15: Rafinaria Navodari | M15: Benzina Euro | O15: Andezit
A16: 11.06.23 | D16: H119TZ | E16: PR405080 | F16: 39350 | G16: 12550 | H16: 26800 | K16: -94 | L16: Rafinaria Navodari | M16: Benzina Euro | O16: Andezit
A17: 11.06.23 | D17: L161MM | E17: MD0844749 | F17: 39760 | G17: 13710 | H17: 26050 | K17: -73 | L17: Rafinaria Navodari | M17: Benzina Euro | O17: Vero-Nadina
A18: 11.06.23 | D18: C825AW | E18: PR405095 | F18: 39130 | G18: 12340 | H18: 26790 | K18: -189 | L18: Rafinaria Navodari | M18: Benzina Euro | O18: Andezit
A20: Итого по Benzina Euro | H20: 106810 | I20: 0 | K20: На сумму | N20: В т.ч. НДС
F21: По документам | H21: 107274 | I21: 0 | K21: 0,00 | N21: 0,00
A23: Дата создания | D23: Номер | E23: Накладная | F23: Брутто | G23: Тара | H23: Получено | I23: Отпущено | K23: Разница кг | L23: Контрагент | M23: Склад | O23: Перевозчик
A24: 11.06.23 | D24: S129JG | E24: MD0844796 | F24: 39350 | G24: 12870 | H24: 26480 | K24: -88 | L24: Rafinaria Navodari | M24: Motorina ADT | O24: Vero-Nadina
A25: 11.06.23 | D25: S635JG | E25: PR405089 | F25: 39070 | G25: 12560 | H25: 26510 | K25: -75 | L25: Rafinaria Navodari | M25: Motorina ADT | O25: Andezit
A26: 11.06.23 | D26: Y374CQ | E26: PR405004 | F26: 39390 | G26: 13190 | H26: 26200 | K26: -152 | L26: Rafinaria Navodari | M26: Motorina ADT | O26: Andezit
A27: 11.06.23 | D27: M212RZ | E27: MD0808271 | F27: 39660 | G27: 12370 | H27: 27290 | K27: -88 | L27: Rafinaria Navodari | M27: Motorina ADT | O27: Vero-Nadina
A28: 11.06.23 | D28: H112TZ | E28: PR404955 | F28: 39920 | G28: 13040 | H28: 26880 | K28: -106 | L28: Rafinaria Navodari | M28: Motorina ADT | O28: Andezit
A30: Итого по Motorina ADT | H30: 133360 | I30: 0 | K30: На сумму | N30: В т.ч. НДС
F31: По документам | H31: 133869 | I31: 0 | K31: 0,00 | N31: 0,00
A33: Дата создания | D33: Номер | E33: Накладная | F33: Брутто | G33: Тара | H33: Получено | I33: Отпущено | K33: Разница кг | L33: Контрагент | M33: Склад | O33: Перевозчик
A34: 11.06.23 | D34: C919RA | E34: AAO1574287 | F34: 39740 | G34: 13970 | H34: 25770 | K34: -88 | L34: Giurgiulesti | M34: Motorina Euro | O34: Andezit
A35: 11.06.23 | D35: W032AL | E35: PR405077 | F35: 39520 | G35: 13580 | H35: 25940 | K35: -60 | L35: Rafinaria Navodari | M35: Motorina Euro | O35: Andezit
A36: 11.06.23 | D36: V778LG | E36: PR405079 | F36: 39810 | G36: 13540 | H36: 26270 | K36: -79 | L36: Rafinaria Navodari | M36: Motorina Euro | O36: Andezit
A37: 11.06.23 | D37: I957WW | E37: PR405042 | F37: 39460 | G37: 13550 | H37: 25910 | K37: -63 | L37: Rafinaria Navodari | M37: Motorina Euro | O37: Andezit
A38: 11.06.23 | D38: H113TZ | E38: PR405028 | F38: 39350 | G38: 12580 | H38: 26770 | K38: -71 | L38: Rafinaria Navodari | M38: Motorina Euro | O38: Andezit
A39: 11.06.23 | D39: X056XC | E39: MD0809598 | F39: 39740 | G39: 13420 | H39: 26320 | K39: -83 | L39: Rafinaria Navodari | M39: Motorina Euro | O39: Vero-Nadina
A40: 11.06.23 | D40: S813JG | E40: MD06300893 | F40: 39560 | G40: 14180 | H40: 25380 | K40: -79 | L40: Rafinaria Navodari | M40: Motorina Euro | O40: Vero-Nadina
A41: 11.06.23 | D41: H110TZ | E41: PR404799 | F41: 39740 | G41: 13470 | H41: 26270 | K41: -69 | L41: Rafinaria Navodari | M41: Motorina Euro | O41: Andezit
A42: 11.06.23 | D42: K015ZJ | E42: PR405088 | F42: 39610 | G42: 13100 | H42: 26510 | K42: -74 | L42: Rafinaria Navodari | M42: Motorina Euro | O42: Andezit
A43: 11.06.23 | D43: S667JG | E43: AAO1574288 | F43: 39890 | G43: 13530 | H43: 26360 | K43: -30 | L43: Giurgiulesti | M43: Motorina Euro | O43: Andezit
A44: 11.06.23 | D44: H924TZ | E44: PR404751 | F44: 38650 | G44: 12320 | H44: 26330 | K44: -92 | L44: Rafinaria Navodari | M44: Motorina Euro | O44: Andezit
A46: Итого по Motorina Euro | H46: 287830 | I46: 0 | K46: На сумму | N46: В т.ч. НДС
F47: По документам | H47: 288618 | I47: 0 | K47: 0,00 | N47: 0,00
A49: Дата создания | D49: Номер | E49: Накладная | F49: Брутто | G49: Тара | H49: Получено | I49: Отпущено | K49: Разница кг | L49: Контрагент | M49: Склад | O49: Перевозчик
A50: 11.06.23 | D50: I854WW | E50: AAE7651680 | F50: 40480 | G50: 13480 | I50: 27000 | K50: -31 | L50: Depozit Chisinau | M50: Diferite | O50: Vero-Nadina
...

Sheet Весы 04.11.2023
A1: Шаблон отчета с группировкой по складам
A3: за период по контрагенту по перевозчику по материалу по складу по транспорту по направлению | C3: 04.11.2023-04.11.2023 <ВСЕ> <ВСЕ> <ВСЕ> <ВСЕ> <ВСЕ> <Любое>
A5: Дата создания | D5: Номер | E5: Накладная | F5: Брутто | G5: Тара | H5: Получено | I5: Отпущено | K5: Разница кг | L5: Контрагент | M5: Склад | O5: Перевозчик
A6: 11.04.23 | D6: K015ZJ | E6: PR405062 | F6: 39570 | G6: 13140 | H6: 26430 | K6: -98 | L6: Rafinaria Navodari | M6: Benzina ADT | O6: Andezit
A7: 11.04.23 | D7: Y698CQ | E7: MD0844781 | F7: 40190 | G7: 14100 | H7: 26090 | K7: -85 | L7: Rafinaria Navodari | M7: Benzina ADT | O7: Vero-Nadina
A8: 11.04.23 | D8: S641JG | E8: PR405068 | F8: 39860 | G8: 13070 | H8: 26790 | K8: -82 | L8: Rafinaria Navodari | M8: Benzina ADT | O8: Andezit
A9: 11.04.23 | D9: I409WW | E9: PR405014 | F9: 38760 | G9: 14180 | H9: 24580 | K9: -88 | L9: Rafinaria Navodari | M9: Benzina ADT | O9: Andezit
A11: Итого по Benzina ADT | H11: 103890 | I11: 0 | K11: На сумму | N11: В т.ч. НДС
F12: По документам | H12: 104243 | I12: 0 | K12: 0,00 | N12: 0,00
A14: Дата создания | D14: Номер | E14: Накладная | F14: Брутто | G14: Тара | H14: Получено | I14: Отпущено | K14: Разница кг | L14: Контрагент | M14: Склад | O14: Перевозчик
A15: 11.04.23 | D15: M170VI | E15: MD0844614 | F15: 39890 | G15: 14280 | H15: 25610 | K15: -96 | L15: Rafinaria Navodari | M15: Benzina Euro | O15: Vero-Nadina
A16: 11.04.23 | D16: I957WW | E16: PR405065 | F16: 39480 | G16: 13440 | H16: 26040 | K16: -72 | L16: Rafinaria Navodari | M16: Benzina Euro | O16: Andezit
A17: 11.04.23 | D17: T521NJ | E17: PR405064 | F17: 39160 | G17: 13090 | H17: 26070 | K17: -79 | L17: Rafinaria Navodari | M17: Benzina Euro | O17: Andezit
A18: 11.04.23 | D18: N974TN | E18: MD0844711 | F18: 39170 | G18: 12450 | H18: 26720 | K18: -54 | L18: Rafinaria Navodari | M18: Benzina Euro | O18: Vero-Nadina
A20: Итого по Benzina Euro | H20: 104440 | I20: 0 | K20: На сумму | N20: В т.ч. НДС
F21: По документам | H21: 104741 | I21: 0 | K21: 0,00 | N21: 0,00
A23: Дата создания | D23: Номер | E23: Накладная | F23: Брутто | G23: Тара | H23: Получено | I23: Отпущено | K23: Разница кг | L23: Контрагент | M23: Склад | O23: Перевозчик
A24: 11.04.23 | D24: I699WW | E24: MD0844631 | F24: 40070 | G24: 12700 | H24: 27370 | K24: -36 | L24: Rafinaria Navodari | M24: Motorina ADT | O24: Vero-Nadina
A26: Итого по Motorina ADT | H26: 27370 | I26: 0 | K26: На сумму | N26: В т.ч. НДС
F27: По документам | H27: 27406 | I27: 0 | K27: 0,00 | N27: 0,00
A29: Дата создания | D29: Номер | E29: Накладная | F29: Брутто | G29: Тара | H29: Получено | I29: Отпущено | K29: Разница кг | L29: Контрагент | M29: Склад | O29: Перевозчик
A30: 11.04.23 | D30: C818RB | E30: AAO1574281 | F30: 38830 | G30: 12390 | H30: 26440 | K30: -66 | L30: Giurgiulesti | M30: Motorina Euro | O30: Andezit
A31: 11.04.23 | D31: C825AW | E31: AAO1574280 | F31: 38540 | G31: 12140 | H31: 26400 | K31: -112 | L31: Giurgiulesti | M31: Motorina Euro | O31: Andezit
A32: 11.04.23 | D32: X360XC | E32: MD0809392 | F32: 39670 | G32: 13460 | H32: 26210 | K32: -67 | L32: Rafinaria Navodari | M32: Motorina Euro | O32: Vero-Nadina
A33: 11.04.23 | D33: C919RA | E33: AAO1574282 | F33: 39400 | G33: 13600 | H33: 25800 | K33: -80 | L33: Giurgiulesti | M33: Motorina Euro | O33: Andezit
A34: 11.04.23 | D34: NSAA982 | E34: AAO1574284 | F34: 40970 | G34: 15150 | H34: 25820 | K34: -20 | L34: Giurgiulesti | M34: Motorina Euro | O34: Vero-Nadina
A35: 11.04.23 | D35: L161MM | E35: MD0844748 | F35: 40140 | G35: 14100 | H35: 26040 | K35: -68 | L35: Rafinaria Navodari | M35: Motorina Euro | O35: Vero-Nadina
A36: 11.04.23 | D36: I289WW | E36: AAO1574283 | F36: 39150 | G36: 13550 | H36: 25600 | K36: -95 | L36: Giurgiulesti | M36: Motorina Euro | O36: Vero-Nadina
A37: 11.04.23 | D37: M531RZ | E37: MD0808369 | F37: 39860 | G37: 12770 | H37: 27090 | K37: -63 | L37: Rafinaria Navodari | M37: Motorina Euro | O37: Vero-Nadina
A38: 11.04.23 | D38: NSAR887 | E38: AAE7651676 | F38: 32300 | G38: 13230 | I38: 19070 | K38: -21 | L38: Depozit Chisinau | M38: Motorina Euro | O38: Vero-Nadina
A39: 11.04.23 | D39: I961WW | E39: PR405070 | F39: 39040 | G39: 13300 | H39: 25740 | K39: -110 | L39: Rafinaria Navodari | M39: Motorina Euro | O39: Andezit
A40: 11.04.23 | D40: NASS703 | E40: AAO1574285 | F40: 40180 | G40: 13710 | H40: 26470 | K40: -80 | L40: Giurgiulesti | M40: Motorina Euro | O40: Vero-Nadina
A41: 11.04.23 | D41: I175WW | E41: AAO1574286 | F41: 40730 | G41: 13570 | H41: 27160 | K41: -11 | L41: Giurgiulesti | M41: Motorina Euro | O41: Vero-Nadina
A43: Итого по Motorina Euro | H43: 288770 | I43: 19070 | K43: На сумму | N43: В т.ч. НДС
F44: По документам | H44: 289542 | I44: 19091 | K44: 0,00 | N44: 0,00
A46: Дата создания | D46: Номер | E46: Накладная | F46: Брутто | G46: Тара | H46: Получено | I46: Отпущено | K46: Разница кг | L46: Контрагент | M46: Склад | O46: Перевозчик
A47: 11.04.23 | D47: I870WW | E47: AAE7651627 | F47: 38100 | G47: 12710 | I47: 25390 | K47: -46 | L47: Depozit Chisinau | M47: Diferite | O47: Vero-Nadina
A48: 11.04.23 | D48: I854WW | E48: AAE7651628.9 | F48: 41270 | G48: 13400 | I48: 27870 | K48: -24 | L48: Depozit Chisinau | M48: Diferite | O48: Vero-Nadina
A49: 11.04.23 | D49: A331AB | E49: AAE7651660.1 | F49: 37800 | G49: 13020 | I49: 24780 | K49: -24 | L49: Depozit Chisinau | M49: Diferite | O49: Vero-Nadina
A50: 11.04.23 | D50: NSAR887 | E50: AAE7651662 | F50: 32820 | G50: 13230 | I50: 19590 | K50: -16 | L50: Depozit Chisinau | M50: Diferite | O50: Vero-Nadina
...

Sheet Весы 03.11.2023
A1: Шаблон отчета с группировкой по складам
A3: за период по контрагенту по перевозчику по материалу по складу по транспорту по направлению | C3: 03.11.2023-03.11.2023 <ВСЕ> <ВСЕ> <ВСЕ> <ВСЕ> <ВСЕ> <Любое>
A5: Дата создания | D5: Номер | E5: Накладная | F5: Брутто | G5: Тара | H5: Получено | I5: Отпущено | K5: Разница кг | L5: Контрагент | M5: Склад | O5: Перевозчик
A6: 11.03.23 | D6: H112TZ | E6: PR389730 | F6: 39550 | G6: 12930 | H6: 26620 | K6: -71 | L6: Rafinaria Navodari | M6: Benzina Euro | O6: Andezit
A7: 11.03.23 | D7: H110TZ | E7: PR405039 | F7: 39390 | G7: 13150 | H7: 26240 | K7: -65 | L7: Rafinaria Navodari | M7: Benzina Euro | O7: Andezit
A8: 11.03.23 | D8: W309AL | E8: MD0808350 | F8: 38680 | G8: 13690 | H8: 24990 | K8: -72 | L8: Rafinaria Navodari | M8: Benzina Euro | O8: Vero-Nadina
A9: 11.03.23 | D9: L690MM | E9: MD0809235 | F9: 38990 | G9: 13240 | H9: 25750 | K9: -62 | L9: Rafinaria Navodari | M9: Benzina Euro | O9: Vero-Nadina
A10: 11.03.23 | D10: M607VI | E10: MD0810034 | F10: 39630 | G10: 13950 | H10: 25680 | K10: -61 | L10: Rafinaria Navodari | M10: Benzina Euro | O10: Andezit
A11: 11.03.23 | D11: Y202CQ | E11: PR404934 | F11: 39550 | G11: 12510 | H11: 27040 | K11: -87 | L11: Rafinaria Navodari | M11: Benzina Euro | O11: Andezit
A13: Итого по Benzina Euro | H13: 156320 | I13: 0 | K13: На сумму | N13: В т.ч. НДС
F14: По документам | H14: 156738 | I14: 0 | K14: 0,00 | N14: 0,00
A16: Дата создания | D16: Номер | E16: Накладная | F16: Брутто | G16: Тара | H16: Получено | I16: Отпущено | K16: Разница кг | L16: Контрагент | M16: Склад | O16: Перевозчик
A17: 11.03.23 | D17: VLG210 | E17: PR404910 | F17: 39030 | G17: 12890 | H17: 26140 | K17: -74 | L17: Rafinaria Navodari | M17: Motorina ADT | O17: Andezit
A18: 11.03.23 | D18: C985AW | E18: PR405066 | F18: 39500 | G18: 12300 | H18: 27200 | K18: -80 | L18: Rafinaria Navodari | M18: Motorina ADT | O18: Andezit
A20: Итого по Motorina ADT | H20: 53340 | I20: 0 | K20: На сумму | N20: В т.ч. НДС
F21: По документам | H21: 53494 | I21: 0 | K21: 0,00 | N21: 0,00
A23: Дата создания | D23: Номер | E23: Накладная | F23: Брутто | G23: Тара | H23: Получено | I23: Отпущено | K23: Разница кг | L23: Контрагент | M23: Склад | O23: Перевозчик
A24: 11.03.23 | D24: BV54LKT | F24: 39800 | G24: 11770 | H24: 28030 | K24: -102 | L24: Rafinaria Navodari | M24: Motorina Euro | O24: LCT
A25: 11.03.23 | D25: C818RB | E25: AAO1574272 | F25: 38600 | G25: 12070 | H25: 26530 | K25: -30 | L25: Giurgiulesti | M25: Motorina Euro | O25: Andezit
A26: 11.03.23 | D26: T289NJ | E26: AAO1574273 | F26: 39650 | G26: 13600 | H26: 26050 | K26: -67 | L26: Giurgiulesti | M26: Motorina Euro | O26: Andezit
A27: 11.03.23 | D27: H119TZ | E27: PR404969 | F27: 39630 | G27: 12710 | H27: 26920 | K27: -50 | L27: Rafinaria Navodari | M27: Motorina Euro | O27: Andezit
A28: 11.03.23 | D28: C823AW | E28: AAO1574275 | F28: 39460 | G28: 13330 | H28: 26130 | K28: -55 | L28: Giurgiulesti | M28: Motorina Euro | O28: Andezit
A29: 11.03.23 | D29: NSAA982 | E29: AAO1574270 | F29: 41120 | G29: 15230 | H29: 25890 | K29: -77 | L29: Giurgiulesti | M29: Motorina Euro | O29: Vero-Nadina
A30: 11.03.23 | D30: I870WW | E30: AAO1574279 | F30: 39280 | G30: 12770 | H30: 26510 | K30: -57 | L30: Giurgiulesti | M30: Motorina Euro | O30: Vero-Nadina
A31: 11.03.23 | D31: I320WW | E31: AAO1574278 | F31: 40050 | G31: 13540 | H31: 26510 | K31: -76 | L31: Giurgiulesti | M31: Motorina Euro | O31: Vero-Nadina
A32: 11.03.23 | D32: C919RA | E32: AAO1574274 | F32: 39720 | G32: 13940 | H32: 25780 | K32: -75 | L32: Giurgiulesti | M32: Motorina Euro | O32: Andezit
A33: 11.03.23 | D33: N173TN | E33: PR404805 | F33: 39500 | G33: 13000 | H33: 26500 | K33: -62 | L33: Rafinaria Navodari | M33: Motorina Euro | O33: Andezit
A34: 11.03.23 | D34: BV95LKT | F34: 39540 | G34: 11730 | H34: 27810 | K34: -74 | L34: Rafinaria Navodari | M34: Motorina Euro | O34: LCT
A35: 11.03.23 | D35: I289WW | E35: AAO1574276 | F35: 39020 | G35: 13330 | H35: 25690 | K35: -38 | L35: Giurgiulesti | M35: Motorina Euro | O35: Vero-Nadina
A36: 11.03.23 | D36: E385RS | E36: PR405061 | F36: 39120 | G36: 13350 | H36: 25770 | K36: -93 | L36: Rafinaria Navodari | M36: Motorina Euro | O36: Andezit
A37: 11.03.23 | D37: VLG212 | E37: PR405067 | F37: 39370 | G37: 13780 | H37: 25590 | K37: -78 | L37: Rafinaria Navodari | M37: Motorina Euro | O37: Andezit
A38: 11.03.23 | D38: NSAA703 | E38: AAO1574277 | F38: 40270 | G38: 13760 | H38: 26510 | K38: -71 | L38: Giurgiulesti | M38: Motorina Euro | O38: Vero-Nadina
A39: 11.03.23 | D39: I855WW | E39: MD0844692 | F39: 39100 | G39: 13000 | H39: 26100 | K39: -69 | L39: Rafinaria Navodari | M39: Motorina Euro | O39: Vero-Nadina
A40: 11.03.23 | D40: M212RZ | E40: MD0808270 | F40: 39670 | G40: 12300 | H40: 27370 | K40: -65 | L40: Rafinaria Navodari | M40: Motorina Euro | O40: Vero-Nadina
A42: Итого по Motorina Euro | H42: 449690 | I42: 0 | K42: На сумму | N42: В т.ч. НДС
F43: По документам | H43: 450829 | I43: 0 | K43: 0,00 | N43: 0,00
A45: Дата создания | D45: Номер | E45: Накладная | F45: Брутто | G45: Тара | H45: Получено | I45: Отпущено | K45: Разница кг | L45: Контрагент | M45: Склад | O45: Перевозчик
A46: 11.03.23 | D46: BV87LKT | F46: 40190 | G46: 12470 | H46: 27720 | K46: -100 | L46: Rafinaria Navodari | M46: Motorina S55 | O46: LCT
A47: 11.03.23 | D47: BV92LKT | F47: 40100 | G47: 11860 | H47: 28240 | K47: -78 | L47: Rafinaria Navodari | M47: Motorina S55 | O47: LCT
A49: Итого по Motorina S55 | H49: 55960 | I49: 0 | K49: На сумму | N49: В т.ч. НДС
...

Sheet Весы 02.11.2023
A1: Шаблон отчета с группировкой по складам
A3: за период по контрагенту по перевозчику по материалу по складу по транспорту по направлению | C3: 02.11.2023-02.11.2023 <ВСЕ> <ВСЕ> <ВСЕ> <ВСЕ> <ВСЕ> <Любое>
A5: Дата создания | D5: Номер | E5: Накладная | F5: Брутто | G5: Тара | H5: Получено | I5: Отпущено | K5: Разница кг | L5: Контрагент | M5: Склад | O5: Перевозчик
A6: 11.02.23 | D6: I957WW | E6: PR404967 | F6: 39400 | G6: 13360 | H6: 26040 | K6: -113 | L6: Rafinaria Navodari | M6: Benzina ADT | O6: Andezit
A7: 11.02.23 | D7: U025TQ | E7: PR404840 | F7: 40040 | G7: 13500 | H7: 26540 | K7: -150 | L7: Rafinaria Navodari | M7: Benzina ADT | O7: Andezit
A9: Итого по Benzina ADT | H9: 52580 | I9: 0 | K9: На сумму | N9: В т.ч. НДС
F10: По документам | H10: 52843 | I10: 0 | K10: 0,00 | N10: 0,00
A12: Дата создания | D12: Номер | E12: Накладная | F12: Брутто | G12: Тара | H12: Получено | I12: Отпущено | K12: Разница кг | L12: Контрагент | M12: Склад | O12: Перевозчик
A13: 11.02.23 | D13: C823AW | E13: PR405034 | F13: 39410 | G13: 13110 | H13: 26300 | K13: -68 | L13: Rafinaria Navodari | M13: Benzina Euro | O13: Andezit
A14: 11.02.23 | D14: T289NJ | E14: PR388986 | F14: 39640 | G14: 13640 | H14: 26000 | K14: -86 | L14: Rafinaria Navodari | M14: Benzina Euro | O14: Andezit
A15: 11.02.23 | D15: T521NJ | E15: PR405017 | F15: 39290 | G15: 13180 | H15: 26110 | K15: -79 | L15: Rafinaria Navodari | M15: Benzina Euro | O15: Andezit
A17: Итого по Benzina Euro | H17: 78410 | I17: 0 | K17: На сумму | N17: В т.ч. НДС
F18: По документам | H18: 78643 | I18: 0 | K18: 0,00 | N18: 0,00
A20: Дата создания | D20: Номер | E20: Накладная | F20: Брутто | G20: Тара | H20: Получено | I20: Отпущено | K20: Разница кг | L20: Контрагент | M20: Склад | O20: Перевозчик
A21: 11.02.23 | D21: M531RZ | E21: MD0808368 | F21: 40110 | G21: 12960 | H21: 27150 | K21: -87 | L21: Rafinaria Navodari | M21: Motorina ADT | O21: Vero-Nadina
A22: 11.02.23 | D22: I967WW | E22: PR405033 | F22: 39130 | G22: 13270 | H22: 25860 | K22: -45 | L22: Rafinaria Navodari | M22: Motorina ADT | O22: Andezit
A23: 11.02.23 | D23: M673VI | E23: PR405018 | F23: 39360 | G23: 12770 | H23: 26590 | K23: -95 | L23: Rafinaria Navodari | M23: Motorina ADT | O23: Andezit
A24: 11.02.23 | D24: O911FC | E24: MD0844643 | F24: 39880 | G24: 12880 | H24: 27000 | K24: -99 | L24: Rafinaria Navodari | M24: Motorina ADT | O24: Vero-Nadina
A26: Итого по Motorina ADT | H26: 106600 | I26: 0 | K26: На сумму | N26: В т.ч. НДС
F27: По документам | H27: 106926 | I27: 0 | K27: 0,00 | N27: 0,00
A29: Дата создания | D29: Номер | E29: Накладная | F29: Брутто | G29: Тара | H29: Получено | I29: Отпущено | K29: Разница кг | L29: Контрагент | M29: Склад | O29: Перевозчик
A30: 11.02.23 | D30: C919RA | E30: AAO1574264 | F30: 39360 | G30: 13630 | H30: 25730 | K30: -40 | L30: Giurgiulesti | M30: Motorina Euro | O30: Andezit
A31: 11.02.23 | D31: C818RB | E31: AAO1574265 | F31: 38730 | G31: 12180 | H31: 26550 | K31: -5 | L31: Giurgiulesti | M31: Motorina Euro | O31: Andezit
A32: 11.02.23 | D32: N974TN | E32: AAO1574266 | F32: 39910 | G32: 12630 | H32: 27280 | K32: -43 | L32: Giurgiulesti | M32: Motorina Euro | O32: Vero-Nadina
A33: 11.02.23 | D33: I289WW | E33: AAO1574267 | F33: 39040 | G33: 13460 | H33: 25580 | K33: -68 | L33: Giurgiulesti | M33: Motorina Euro | O33: Vero-Nadina
A34: 11.02.23 | D34: A098AB | E34: AAO1574269 | F34: 40130 | G34: 13690 | H34: 26440 | K34: -52 | L34: Giurgiulesti | M34: Motorina Euro | O34: Vero-Nadina
A35: 11.02.23 | D35: NSAA703 | E35: AAO1574268 | F35: 40200 | G35: 13740 | H35: 26460 | K35: -50 | L35: Giurgiulesti | M35: Motorina Euro | O35: Vero-Nadina
A36: 11.02.23 | D36: V774LG | E36: PR404946 | F36: 39670 | G36: 12650 | H36: 27020 | K36: -76 | L36: Rafinaria Navodari | M36: Motorina Euro | O36: Andezit
A37: 11.02.23 | D37: I175WW | E37: AAO1574271 | F37: 40620 | G37: 13530 | H37: 27090 | K37: -102 | L37: Giurgiulesti | M37: Motorina Euro | O37: Vero-Nadina
A38: 11.02.23 | D38: V779LG | E38: PR405015 | F38: 39630 | G38: 12970 | H38: 26660 | K38: -61 | L38: Rafinaria Navodari | M38: Motorina Euro | O38: Andezit
A39: 11.02.23 | D39: NSAA984 | E39: PR0678048 | F39: 39320 | G39: 13650 | H39: 25670 | K39: -170 | L39: Rafinaria Navodari | M39: Motorina Euro | O39: Vero-Nadina
A40: 11.02.23 | D40: X056XC | E40: MD0809597 | F40: 39950 | G40: 13500 | H40: 26450 | K40: -63 | L40: Rafinaria Navodari | M40: Motorina Euro | O40: Vero-Nadina
A41: 11.02.23 | D41: H120TZ | E41: PR405040 | F41: 39430 | G41: 12730 | H41: 26700 | K41: -67 | L41: Rafinaria Navodari | M41: Motorina Euro | O41: Andezit
A42: 11.02.23 | D42: BV94LKT | F42: 39460 | G42: 11540 | H42: 27920 | K42: -102 | L42: Rafinaria Navodari | M42: Motorina Euro | O42: LCT
A44: Итого по Motorina Euro | H44: 345550 | I44: 0 | K44: На сумму | N44: В т.ч. НДС
F45: По документам | H45: 346449 | I45: 0 | K45: 0,00 | N45: 0,00
A47: Дата создания | D47: Номер | E47: Накладная | F47: Брутто | G47: Тара | H47: Получено | I47: Отпущено | K47: Разница кг | L47: Контрагент | M47: Склад | O47: Перевозчик
A48: 11.02.23 | D48: V193LG | E48: AAE7651568 | F48: 38300 | G48: 13930 | I48: 24370 | K48: -1 | L48: Depozit Chisinau | M48: Diferite | O48: Andezit
A49: 11.02.23 | D49: NSAB041 | E49: AAE7651565 | F49: 39140 | G49: 13560 | I49: 25580 | K49: -38 | L49: Depozit Chisinau | M49: Diferite | O49: Vero-Nadina
A50: 11.02.23 | D50: A014AB | E50: AAE7651566.7 | F50: 39660 | G50: 13040 | I50: 26620 | K50: -33 | L50: Depozit Chisinau | M50: Diferite | O50: Andezit
...

Sheet Весы 01.11.2023
A1: Шаблон отчета с группировкой по складам
A3: за период по контрагенту по перевозчику по материалу по складу по транспорту по направлению | C3: 01.11.2023-01.11.2023 <ВСЕ> <ВСЕ> <ВСЕ> <ВСЕ> <ВСЕ> <Любое>
A5: Дата создания | D5: Номер | E5: Накладная | F5: Брутто | G5: Тара | H5: Получено | I5: Отпущено | K5: Разница кг | L5: Контрагент | M5: Склад | O5: Перевозчик
A6: 11.01.23 | D6: K015ZJ | E6: PR405009 | F6: 39430 | G6: 13180 | H6: 26250 | K6: -71 | L6: Rafinaria Navodari | M6: Benzina ADT | O6: Andezit
A7: 11.01.23 | D7: C922RA | E7: PR405012 | F7: 39220 | G7: 13640 | H7: 25580 | K7: -95 | L7: Rafinaria Navodari | M7: Benzina ADT | O7: Andezit
A8: 11.01.23 | D8: X360XC | E8: MD0809391 | F8: 39460 | G8: 13350 | H8: 26110 | K8: -98 | L8: Rafinaria Navodari | M8: Benzina ADT | O8: Vero-Nadina
A9: 11.01.23 | D9: M170VI | E9: MD0844613 | F9: 39940 | G9: 14260 | H9: 25680 | K9: -81 | L9: Rafinaria Navodari | M9: Benzina ADT | O9: Vero-Nadina
A11: Итого по Benzina ADT | H11: 103620 | I11: 0 | K11: На сумму | N11: В т.ч. НДС
F12: По документам | H12: 103965 | I12: 0 | K12: 0,00 | N12: 0,00
A14: Дата создания | D14: Номер | E14: Накладная | F14: Брутто | G14: Тара | H14: Получено | I14: Отпущено | K14: Разница кг | L14: Контрагент | M14: Склад | O14: Перевозчик
A15: 11.01.23 | D15: V778LG | E15: PR404911 | F15: 39610 | G15: 13460 | H15: 26150 | K15: -96 | L15: Rafinaria Navodari | M15: Benzina Euro | O15: Andezit
A16: 11.01.23 | D16: T514NJ | E16: PR404990 | F16: 39260 | G16: 13220 | H16: 26040 | K16: -90 | L16: Rafinaria Navodari | M16: Benzina Euro | O16: Andezit
A17: 11.01.23 | D17: VLG210 | E17: PR404996 | F17: 39020 | G17: 12800 | H17: 26220 | K17: -86 | L17: Rafinaria Navodari | M17: Benzina Euro | O17: Andezit
A18: 11.01.23 | D18: Y367CQ | E18: PR405010 | F18: 39240 | G18: 12620 | H18: 26620 | K18: -143 | L18: Rafinaria Navodari | M18: Benzina Euro | O18: Andezit
A19: 11.01.23 | D19: H917TZ | E19: PR404982 | F19: 39490 | G19: 12920 | H19: 26570 | K19: -88 | L19: Rafinaria Navodari | M19: Benzina Euro | O19: Andezit
A20: 11.01.23 | D20: E385RS | E20: PR404995 | F20: 38850 | G20: 13260 | H20: 25590 | K20: -62 | L20: Rafinaria Navodari | M20: Benzina Euro | O20: Andezit
A21: 11.01.23 | D21: I856WW | E21: MD0844774 | F21: 39440 | G21: 12950 | H21: 26490 | K21: -158 | L21: Rafinaria Navodari | M21: Benzina Euro | O21: Vero-Nadina
A22: 11.01.23 | D22: I855WW | E22: MD0844691 | F22: 39340 | G22: 13180 | H22: 26160 | K22: -98 | L22: Rafinaria Navodari | M22: Benzina Euro | O22: Vero-Nadina
A24: Итого по Benzina Euro | H24: 209840 | I24: 0 | K24: На сумму | N24: В т.ч. НДС
F25: По документам | H25: 210661 | I25: 0 | K25: 0,00 | N25: 0,00
A27: Дата создания | D27: Номер | E27: Накладная | F27: Брутто | G27: Тара | H27: Получено | I27: Отпущено | K27: Разница кг | L27: Контрагент | M27: Склад | O27: Перевозчик
A28: 11.01.23 | D28: BV92LKT | F28: 39920 | G28: 11870 | H28: 28050 | K28: -108 | L28: Rafinaria Navodari | M28: Motorina ADT | O28: LCT
A29: 11.01.23 | D29: Y202CQ | E29: PR404999 | F29: 39540 | G29: 12430 | H29: 27110 | K29: -54 | L29: Rafinaria Navodari | M29: Motorina ADT | O29: Andezit
A31: Итого по Motorina ADT | H31: 55160 | I31: 0 | K31: На сумму | N31: В т.ч. НДС
F32: По документам | H32: 55322 | I32: 0 | K32: 0,00 | N32: 0,00
A34: Дата создания | D34: Номер | E34: Накладная | F34: Брутто | G34: Тара | H34: Получено | I34: Отпущено | K34: Разница кг | L34: Контрагент | M34: Склад | O34: Перевозчик
A35: 11.01.23 | D35: E607RR | E35: AAO1574259 | F35: 39220 | G35: 14350 | H35: 24870 | K35: -60 | L35: Giurgiulesti | M35: Motorina Euro | O35: Vero-Nadina
A36: 11.01.23 | D36: C919RA | E36: AAO1574261 | F36: 39770 | G36: 14070 | H36: 25700 | K36: -97 | L36: Giurgiulesti | M36: Motorina Euro | O36: Andezit
A37: 11.01.23 | D37: C818RB | E37: AAO1574260 | F37: 38720 | G37: 12350 | H37: 26370 | K37: -51 | L37: Giurgiulesti | M37: Motorina Euro | O37: Andezit
A38: 11.01.23 | D38: I289WW | E38: AAO1574262 | F38: 39120 | G38: 13530 | H38: 25590 | K38: -40 | L38: Giurgiulesti | M38: Motorina Euro | O38: Vero-Nadina
A39: 11.01.23 | D39: I521LG | E39: MD0808682 | F39: 39940 | G39: 13390 | H39: 26550 | K39: -68 | L39: Rafinaria Navodari | M39: Motorina Euro | O39: Vero-Nadina
A40: 11.01.23 | D40: Z778PT | E40: PR404916 | F40: 39540 | G40: 13130 | H40: 26410 | K40: -89 | L40: Rafinaria Navodari | M40: Motorina Euro | O40: Andezit
A41: 11.01.23 | D41: V739LG | E41: PR405026 | F41: 39220 | G41: 12790 | H41: 26430 | K41: -63 | L41: Rafinaria Navodari | M41: Motorina Euro | O41: Andezit
A42: 11.01.23 | D42: V772LG | E42: PR404613 | F42: 39480 | G42: 13260 | H42: 26220 | K42: -106 | L42: Rafinaria Navodari | M42: Motorina Euro | O42: Andezit
A43: 11.01.23 | D43: NS206AB | E43: AAO1574263 | F43: 39810 | G43: 12920 | H43: 26890 | K43: -64 | L43: Giurgiulesti | M43: Motorina Euro | O43: Vero-Nadina
A45: Итого по Motorina Euro | H45: 235030 | I45: 0 | K45: На сумму | N45: В т.ч. НДС
F46: По документам | H46: 235668 | I46: 0 | K46: 0,00 | N46: 0,00
A48: Дата создания | D48: Номер | E48: Накладная | F48: Брутто | G48: Тара | H48: Получено | I48: Отпущено | K48: Разница кг | L48: Контрагент | M48: Склад | O48: Перевозчик
A49: 11.01.23 | D49: A331AB | E49: AAE7651556 | F49: 38000 | G49: 13220 | I49: 24780 | K49: -55 | L49: Depozit Chisinau | M49: Diferite | O49: Vero-Nadina
A50: 11.01.23 | D50: NSAB055 | E50: AAE7651558 | F50: 39870 | G50: 13410 | I50: 26460 | K50: -43 | L50: Depozit Chisinau | M50: Diferite | O50: Vero-Nadina
...
